Internal Server Error: /words_list/
Traceback (most recent call last):
  File "/home/user/.pyenv/versions/django/lib/python3.9/site-packages/django/core/handlers/exception.py", line 55, in inner
    response = get_response(request)
  File "/home/user/.pyenv/versions/django/lib/python3.9/site-packages/django/core/handlers/base.py", line 197, in _get_response
    response = wrapped_callback(request, *callback_args, **callback_kwargs)
  File "/home/user/stepik_django/maincourse/mainapp/views.py", line 8, in dictionary
    with open('dictionary.txt', 'r') as file:
FileNotFoundError: [Errno 2] No such file or directory: 'dictionary.txt'
"GET /words_list/ HTTP/1.1" 500 65553
Internal Server Error: /words_list/
Traceback (most recent call last):
  File "/home/user/.pyenv/versions/django/lib/python3.9/site-packages/django/core/handlers/exception.py", line 55, in inner
    response = get_response(request)
  File "/home/user/.pyenv/versions/django/lib/python3.9/site-packages/django/core/handlers/base.py", line 197, in _get_response
    response = wrapped_callback(request, *callback_args, **callback_kwargs)
  File "/home/user/stepik_django/maincourse/mainapp/views.py", line 8, in dictionary
    with open('dictionary.txt', 'r') as file:
FileNotFoundError: [Errno 2] No such file or directory: 'dictionary.txt'
"GET /words_list/ HTTP/1.1" 500 65553
Internal Server Error: /words_list/
Traceback (most recent call last):
  File "/home/user/.pyenv/versions/django/lib/python3.9/site-packages/django/core/handlers/exception.py", line 55, in inner
    response = get_response(request)
  File "/home/user/.pyenv/versions/django/lib/python3.9/site-packages/django/core/handlers/base.py", line 197, in _get_response
    response = wrapped_callback(request, *callback_args, **callback_kwargs)
  File "/home/user/stepik_django/maincourse/mainapp/views.py", line 8, in dictionary
    with open('dictionary.txt', 'r') as file:
FileNotFoundError: [Errno 2] No such file or directory: 'dictionary.txt'
"GET /words_list/ HTTP/1.1" 500 65553
Internal Server Error: /words_list/
Traceback (most recent call last):
  File "/home/user/.pyenv/versions/django/lib/python3.9/site-packages/django/core/handlers/exception.py", line 55, in inner
    response = get_response(request)
  File "/home/user/.pyenv/versions/django/lib/python3.9/site-packages/django/core/handlers/base.py", line 197, in _get_response
    response = wrapped_callback(request, *callback_args, **callback_kwargs)
  File "/home/user/stepik_django/maincourse/mainapp/views.py", line 8, in dictionary
    with open('dictionary.txt', 'r') as file:
FileNotFoundError: [Errno 2] No such file or directory: 'dictionary.txt'
"GET /words_list/ HTTP/1.1" 500 65553
Internal Server Error: /add_word/
Traceback (most recent call last):
  File "/home/user/.pyenv/versions/django/lib/python3.9/site-packages/django/utils/datastructures.py", line 84, in __getitem__
    list_ = super().__getitem__(key)
KeyError: 'word'

During handling of the above exception, another exception occurred:

Traceback (most recent call last):
  File "/home/user/.pyenv/versions/django/lib/python3.9/site-packages/django/core/handlers/exception.py", line 55, in inner
    response = get_response(request)
  File "/home/user/.pyenv/versions/django/lib/python3.9/site-packages/django/core/handlers/base.py", line 197, in _get_response
    response = wrapped_callback(request, *callback_args, **callback_kwargs)
  File "/home/user/stepik_django/maincourse/mainapp/views.py", line 14, in add_word
    word = data['word']
  File "/home/user/.pyenv/versions/django/lib/python3.9/site-packages/django/utils/datastructures.py", line 86, in __getitem__
    raise MultiValueDictKeyError(key)
django.utils.datastructures.MultiValueDictKeyError: 'word'
"GET /add_word/ HTTP/1.1" 500 73622
Internal Server Error: /words_list/
Traceback (most recent call last):
  File "/home/user/.pyenv/versions/django/lib/python3.9/site-packages/django/core/handlers/exception.py", line 55, in inner
    response = get_response(request)
  File "/home/user/.pyenv/versions/django/lib/python3.9/site-packages/django/core/handlers/base.py", line 197, in _get_response
    response = wrapped_callback(request, *callback_args, **callback_kwargs)
  File "/home/user/stepik_django/maincourse/mainapp/views.py", line 8, in dictionary
    with open('dictionary.txt', 'r') as file:
FileNotFoundError: [Errno 2] No such file or directory: 'dictionary.txt'
"GET /words_list/ HTTP/1.1" 500 65553
Internal Server Error: /words_list/
Traceback (most recent call last):
  File "/home/user/.pyenv/versions/django/lib/python3.9/site-packages/django/core/handlers/exception.py", line 55, in inner
    response = get_response(request)
  File "/home/user/.pyenv/versions/django/lib/python3.9/site-packages/django/core/handlers/base.py", line 197, in _get_response
    response = wrapped_callback(request, *callback_args, **callback_kwargs)
  File "/home/user/stepik_django/maincourse/mainapp/views.py", line 8, in dictionary
    with open('dictionary.txt', 'r') as file:
FileNotFoundError: [Errno 2] No such file or directory: 'dictionary.txt'
"GET /words_list/ HTTP/1.1" 500 65553
Internal Server Error: /words_list/
Traceback (most recent call last):
  File "/home/user/.pyenv/versions/django/lib/python3.9/site-packages/django/core/handlers/exception.py", line 55, in inner
    response = get_response(request)
  File "/home/user/.pyenv/versions/django/lib/python3.9/site-packages/django/core/handlers/base.py", line 197, in _get_response
    response = wrapped_callback(request, *callback_args, **callback_kwargs)
  File "/home/user/stepik_django/maincourse/mainapp/views.py", line 8, in dictionary
    with open('dictionary.txt', 'r') as file:
FileNotFoundError: [Errno 2] No such file or directory: 'dictionary.txt'
"GET /words_list/ HTTP/1.1" 500 65553
Internal Server Error: /words_list/
Traceback (most recent call last):
  File "/home/user/.pyenv/versions/django/lib/python3.9/site-packages/django/core/handlers/exception.py", line 55, in inner
    response = get_response(request)
  File "/home/user/.pyenv/versions/django/lib/python3.9/site-packages/django/core/handlers/base.py", line 197, in _get_response
    response = wrapped_callback(request, *callback_args, **callback_kwargs)
  File "/home/user/stepik_django/maincourse/mainapp/views.py", line 10, in dictionary
    return render(request, 'dictionary.html', content)
  File "/home/user/.pyenv/versions/django/lib/python3.9/site-packages/django/shortcuts.py", line 24, in render
    content = loader.render_to_string(template_name, context, request, using=using)
  File "/home/user/.pyenv/versions/django/lib/python3.9/site-packages/django/template/loader.py", line 62, in render_to_string
    return template.render(context, request)
  File "/home/user/.pyenv/versions/django/lib/python3.9/site-packages/django/template/backends/django.py", line 57, in render
    context = make_context(
  File "/home/user/.pyenv/versions/django/lib/python3.9/site-packages/django/template/context.py", line 278, in make_context
    raise TypeError(
TypeError: context must be a dict rather than list.
"GET /words_list/ HTTP/1.1" 500 82588
Internal Server Error: /add_word/
Traceback (most recent call last):
  File "/home/user/.pyenv/versions/django/lib/python3.9/site-packages/django/utils/datastructures.py", line 84, in __getitem__
    list_ = super().__getitem__(key)
KeyError: 'word'

During handling of the above exception, another exception occurred:

Traceback (most recent call last):
  File "/home/user/.pyenv/versions/django/lib/python3.9/site-packages/django/core/handlers/exception.py", line 55, in inner
    response = get_response(request)
  File "/home/user/.pyenv/versions/django/lib/python3.9/site-packages/django/core/handlers/base.py", line 197, in _get_response
    response = wrapped_callback(request, *callback_args, **callback_kwargs)
  File "/home/user/stepik_django/maincourse/mainapp/views.py", line 14, in add_word
    word = data['word']
  File "/home/user/.pyenv/versions/django/lib/python3.9/site-packages/django/utils/datastructures.py", line 86, in __getitem__
    raise MultiValueDictKeyError(key)
django.utils.datastructures.MultiValueDictKeyError: 'word'
"GET /add_word/ HTTP/1.1" 500 73643
Internal Server Error: /add_word/
Traceback (most recent call last):
  File "/home/user/.pyenv/versions/django/lib/python3.9/site-packages/django/utils/datastructures.py", line 84, in __getitem__
    list_ = super().__getitem__(key)
KeyError: 'word'

During handling of the above exception, another exception occurred:

Traceback (most recent call last):
  File "/home/user/.pyenv/versions/django/lib/python3.9/site-packages/django/core/handlers/exception.py", line 55, in inner
    response = get_response(request)
  File "/home/user/.pyenv/versions/django/lib/python3.9/site-packages/django/core/handlers/base.py", line 197, in _get_response
    response = wrapped_callback(request, *callback_args, **callback_kwargs)
  File "/home/user/stepik_django/maincourse/mainapp/views.py", line 14, in add_word
    word = data['word']
  File "/home/user/.pyenv/versions/django/lib/python3.9/site-packages/django/utils/datastructures.py", line 86, in __getitem__
    raise MultiValueDictKeyError(key)
django.utils.datastructures.MultiValueDictKeyError: 'word'
"GET /add_word/ HTTP/1.1" 500 73643
Internal Server Error: /add_word/
Traceback (most recent call last):
  File "/home/user/.pyenv/versions/django/lib/python3.9/site-packages/django/utils/datastructures.py", line 84, in __getitem__
    list_ = super().__getitem__(key)
KeyError: 'word'

During handling of the above exception, another exception occurred:

Traceback (most recent call last):
  File "/home/user/.pyenv/versions/django/lib/python3.9/site-packages/django/core/handlers/exception.py", line 55, in inner
    response = get_response(request)
  File "/home/user/.pyenv/versions/django/lib/python3.9/site-packages/django/core/handlers/base.py", line 197, in _get_response
    response = wrapped_callback(request, *callback_args, **callback_kwargs)
  File "/home/user/stepik_django/maincourse/mainapp/views.py", line 14, in add_word
    word = data['word']
  File "/home/user/.pyenv/versions/django/lib/python3.9/site-packages/django/utils/datastructures.py", line 86, in __getitem__
    raise MultiValueDictKeyError(key)
django.utils.datastructures.MultiValueDictKeyError: 'word'
"GET /add_word/ HTTP/1.1" 500 73643
Internal Server Error: /add_word/
Traceback (most recent call last):
  File "/home/user/.pyenv/versions/django/lib/python3.9/site-packages/django/utils/datastructures.py", line 84, in __getitem__
    list_ = super().__getitem__(key)
KeyError: 'word'

During handling of the above exception, another exception occurred:

Traceback (most recent call last):
  File "/home/user/.pyenv/versions/django/lib/python3.9/site-packages/django/core/handlers/exception.py", line 55, in inner
    response = get_response(request)
  File "/home/user/.pyenv/versions/django/lib/python3.9/site-packages/django/core/handlers/base.py", line 197, in _get_response
    response = wrapped_callback(request, *callback_args, **callback_kwargs)
  File "/home/user/stepik_django/maincourse/mainapp/views.py", line 14, in add_word
    word = data['word']
  File "/home/user/.pyenv/versions/django/lib/python3.9/site-packages/django/utils/datastructures.py", line 86, in __getitem__
    raise MultiValueDictKeyError(key)
django.utils.datastructures.MultiValueDictKeyError: 'word'
"GET /add_word/ HTTP/1.1" 500 73643
Internal Server Error: /add_word/
Traceback (most recent call last):
  File "/home/user/.pyenv/versions/django/lib/python3.9/site-packages/django/utils/datastructures.py", line 84, in __getitem__
    list_ = super().__getitem__(key)
KeyError: 'word'

During handling of the above exception, another exception occurred:

Traceback (most recent call last):
  File "/home/user/.pyenv/versions/django/lib/python3.9/site-packages/django/core/handlers/exception.py", line 55, in inner
    response = get_response(request)
  File "/home/user/.pyenv/versions/django/lib/python3.9/site-packages/django/core/handlers/base.py", line 197, in _get_response
    response = wrapped_callback(request, *callback_args, **callback_kwargs)
  File "/home/user/stepik_django/maincourse/mainapp/views.py", line 14, in add_word
    word = data['word']
  File "/home/user/.pyenv/versions/django/lib/python3.9/site-packages/django/utils/datastructures.py", line 86, in __getitem__
    raise MultiValueDictKeyError(key)
django.utils.datastructures.MultiValueDictKeyError: 'word'
"GET /add_word/ HTTP/1.1" 500 73643
Internal Server Error: /add_word/
Traceback (most recent call last):
  File "/home/user/.pyenv/versions/django/lib/python3.9/site-packages/django/utils/datastructures.py", line 84, in __getitem__
    list_ = super().__getitem__(key)
KeyError: 'word'

During handling of the above exception, another exception occurred:

Traceback (most recent call last):
  File "/home/user/.pyenv/versions/django/lib/python3.9/site-packages/django/core/handlers/exception.py", line 55, in inner
    response = get_response(request)
  File "/home/user/.pyenv/versions/django/lib/python3.9/site-packages/django/core/handlers/base.py", line 197, in _get_response
    response = wrapped_callback(request, *callback_args, **callback_kwargs)
  File "/home/user/stepik_django/maincourse/mainapp/views.py", line 14, in add_word
    word = data['word']
  File "/home/user/.pyenv/versions/django/lib/python3.9/site-packages/django/utils/datastructures.py", line 86, in __getitem__
    raise MultiValueDictKeyError(key)
django.utils.datastructures.MultiValueDictKeyError: 'word'
"GET /add_word/ HTTP/1.1" 500 73643
Internal Server Error: /add_word/
Traceback (most recent call last):
  File "/home/user/.pyenv/versions/django/lib/python3.9/site-packages/django/core/handlers/exception.py", line 55, in inner
    response = get_response(request)
  File "/home/user/.pyenv/versions/django/lib/python3.9/site-packages/django/core/handlers/base.py", line 197, in _get_response
    response = wrapped_callback(request, *callback_args, **callback_kwargs)
  File "/home/user/stepik_django/maincourse/mainapp/views.py", line 14, in add_word
    word = data['word']
KeyError: 'word'
"GET /add_word/ HTTP/1.1" 500 65285
Internal Server Error: /add_word/
Traceback (most recent call last):
  File "/home/user/.pyenv/versions/django/lib/python3.9/site-packages/django/utils/datastructures.py", line 84, in __getitem__
    list_ = super().__getitem__(key)
KeyError: 'word'

During handling of the above exception, another exception occurred:

Traceback (most recent call last):
  File "/home/user/.pyenv/versions/django/lib/python3.9/site-packages/django/core/handlers/exception.py", line 55, in inner
    response = get_response(request)
  File "/home/user/.pyenv/versions/django/lib/python3.9/site-packages/django/core/handlers/base.py", line 197, in _get_response
    response = wrapped_callback(request, *callback_args, **callback_kwargs)
  File "/home/user/stepik_django/maincourse/mainapp/views.py", line 14, in add_word
    word = data['word']
  File "/home/user/.pyenv/versions/django/lib/python3.9/site-packages/django/utils/datastructures.py", line 86, in __getitem__
    raise MultiValueDictKeyError(key)
django.utils.datastructures.MultiValueDictKeyError: 'word'
"GET /add_word/ HTTP/1.1" 500 73643
Internal Server Error: /add_word/
Traceback (most recent call last):
  File "/home/user/.pyenv/versions/django/lib/python3.9/site-packages/django/core/handlers/exception.py", line 55, in inner
    response = get_response(request)
  File "/home/user/.pyenv/versions/django/lib/python3.9/site-packages/django/core/handlers/base.py", line 197, in _get_response
    response = wrapped_callback(request, *callback_args, **callback_kwargs)
  File "/home/user/stepik_django/maincourse/mainapp/views.py", line 14, in add_word
    return render(request, 'add_form')
  File "/home/user/.pyenv/versions/django/lib/python3.9/site-packages/django/shortcuts.py", line 24, in render
    content = loader.render_to_string(template_name, context, request, using=using)
  File "/home/user/.pyenv/versions/django/lib/python3.9/site-packages/django/template/loader.py", line 61, in render_to_string
    template = get_template(template_name, using=using)
  File "/home/user/.pyenv/versions/django/lib/python3.9/site-packages/django/template/loader.py", line 19, in get_template
    raise TemplateDoesNotExist(template_name, chain=chain)
django.template.exceptions.TemplateDoesNotExist: add_form
"GET /add_word/ HTTP/1.1" 500 80238
Internal Server Error: /words_list/
Traceback (most recent call last):
  File "/home/user/.pyenv/versions/django/lib/python3.9/site-packages/django/core/handlers/exception.py", line 55, in inner
    response = get_response(request)
  File "/home/user/.pyenv/versions/django/lib/python3.9/site-packages/django/core/handlers/base.py", line 197, in _get_response
    response = wrapped_callback(request, *callback_args, **callback_kwargs)
  File "/home/user/stepik_django/maincourse/mainapp/views.py", line 10, in dictionary
    return render(request, 'dictionary.html', content)
  File "/home/user/.pyenv/versions/django/lib/python3.9/site-packages/django/shortcuts.py", line 24, in render
    content = loader.render_to_string(template_name, context, request, using=using)
  File "/home/user/.pyenv/versions/django/lib/python3.9/site-packages/django/template/loader.py", line 61, in render_to_string
    template = get_template(template_name, using=using)
  File "/home/user/.pyenv/versions/django/lib/python3.9/site-packages/django/template/loader.py", line 15, in get_template
    return engine.get_template(template_name)
  File "/home/user/.pyenv/versions/django/lib/python3.9/site-packages/django/template/backends/django.py", line 33, in get_template
    return Template(self.engine.get_template(template_name), self)
  File "/home/user/.pyenv/versions/django/lib/python3.9/site-packages/django/template/engine.py", line 175, in get_template
    template, origin = self.find_template(template_name)
  File "/home/user/.pyenv/versions/django/lib/python3.9/site-packages/django/template/engine.py", line 157, in find_template
    template = loader.get_template(name, skip=skip)
  File "/home/user/.pyenv/versions/django/lib/python3.9/site-packages/django/template/loaders/cached.py", line 57, in get_template
    template = super().get_template(template_name, skip)
  File "/home/user/.pyenv/versions/django/lib/python3.9/site-packages/django/template/loaders/base.py", line 28, in get_template
    return Template(
  File "/home/user/.pyenv/versions/django/lib/python3.9/site-packages/django/template/base.py", line 154, in __init__
    self.nodelist = self.compile_nodelist()
  File "/home/user/.pyenv/versions/django/lib/python3.9/site-packages/django/template/base.py", line 200, in compile_nodelist
    return parser.parse()
  File "/home/user/.pyenv/versions/django/lib/python3.9/site-packages/django/template/base.py", line 484, in parse
    raise self.error(token, e)
  File "/home/user/.pyenv/versions/django/lib/python3.9/site-packages/django/template/base.py", line 482, in parse
    filter_expression = self.compile_filter(token.contents)
  File "/home/user/.pyenv/versions/django/lib/python3.9/site-packages/django/template/base.py", line 600, in compile_filter
    return FilterExpression(token, self)
  File "/home/user/.pyenv/versions/django/lib/python3.9/site-packages/django/template/base.py", line 703, in __init__
    raise TemplateSyntaxError(
django.template.exceptions.TemplateSyntaxError: Could not parse the remainder: '[0]' from 'words[0]'
"GET /words_list/ HTTP/1.1" 500 136481
Internal Server Error: /words_list/
Traceback (most recent call last):
  File "/home/user/.pyenv/versions/django/lib/python3.9/site-packages/django/core/handlers/exception.py", line 55, in inner
    response = get_response(request)
  File "/home/user/.pyenv/versions/django/lib/python3.9/site-packages/django/core/handlers/base.py", line 197, in _get_response
    response = wrapped_callback(request, *callback_args, **callback_kwargs)
  File "/home/user/stepik_django/maincourse/mainapp/views.py", line 10, in dictionary
    return render(request, 'dictionary.html', content)
  File "/home/user/.pyenv/versions/django/lib/python3.9/site-packages/django/shortcuts.py", line 24, in render
    content = loader.render_to_string(template_name, context, request, using=using)
  File "/home/user/.pyenv/versions/django/lib/python3.9/site-packages/django/template/loader.py", line 61, in render_to_string
    template = get_template(template_name, using=using)
  File "/home/user/.pyenv/versions/django/lib/python3.9/site-packages/django/template/loader.py", line 15, in get_template
    return engine.get_template(template_name)
  File "/home/user/.pyenv/versions/django/lib/python3.9/site-packages/django/template/backends/django.py", line 33, in get_template
    return Template(self.engine.get_template(template_name), self)
  File "/home/user/.pyenv/versions/django/lib/python3.9/site-packages/django/template/engine.py", line 175, in get_template
    template, origin = self.find_template(template_name)
  File "/home/user/.pyenv/versions/django/lib/python3.9/site-packages/django/template/engine.py", line 157, in find_template
    template = loader.get_template(name, skip=skip)
  File "/home/user/.pyenv/versions/django/lib/python3.9/site-packages/django/template/loaders/cached.py", line 57, in get_template
    template = super().get_template(template_name, skip)
  File "/home/user/.pyenv/versions/django/lib/python3.9/site-packages/django/template/loaders/base.py", line 28, in get_template
    return Template(
  File "/home/user/.pyenv/versions/django/lib/python3.9/site-packages/django/template/base.py", line 154, in __init__
    self.nodelist = self.compile_nodelist()
  File "/home/user/.pyenv/versions/django/lib/python3.9/site-packages/django/template/base.py", line 200, in compile_nodelist
    return parser.parse()
  File "/home/user/.pyenv/versions/django/lib/python3.9/site-packages/django/template/base.py", line 484, in parse
    raise self.error(token, e)
  File "/home/user/.pyenv/versions/django/lib/python3.9/site-packages/django/template/base.py", line 482, in parse
    filter_expression = self.compile_filter(token.contents)
  File "/home/user/.pyenv/versions/django/lib/python3.9/site-packages/django/template/base.py", line 600, in compile_filter
    return FilterExpression(token, self)
  File "/home/user/.pyenv/versions/django/lib/python3.9/site-packages/django/template/base.py", line 703, in __init__
    raise TemplateSyntaxError(
django.template.exceptions.TemplateSyntaxError: Could not parse the remainder: '[0]' from 'words[0]'
"GET /words_list/ HTTP/1.1" 500 136586
Internal Server Error: /words_list/
Traceback (most recent call last):
  File "/home/user/.pyenv/versions/django/lib/python3.9/site-packages/django/core/handlers/exception.py", line 55, in inner
    response = get_response(request)
  File "/home/user/.pyenv/versions/django/lib/python3.9/site-packages/django/core/handlers/base.py", line 197, in _get_response
    response = wrapped_callback(request, *callback_args, **callback_kwargs)
  File "/home/user/stepik_django/maincourse/mainapp/views.py", line 10, in dictionary
    return render(request, 'dictionary.html', content)
  File "/home/user/.pyenv/versions/django/lib/python3.9/site-packages/django/shortcuts.py", line 24, in render
    content = loader.render_to_string(template_name, context, request, using=using)
  File "/home/user/.pyenv/versions/django/lib/python3.9/site-packages/django/template/loader.py", line 61, in render_to_string
    template = get_template(template_name, using=using)
  File "/home/user/.pyenv/versions/django/lib/python3.9/site-packages/django/template/loader.py", line 15, in get_template
    return engine.get_template(template_name)
  File "/home/user/.pyenv/versions/django/lib/python3.9/site-packages/django/template/backends/django.py", line 33, in get_template
    return Template(self.engine.get_template(template_name), self)
  File "/home/user/.pyenv/versions/django/lib/python3.9/site-packages/django/template/engine.py", line 175, in get_template
    template, origin = self.find_template(template_name)
  File "/home/user/.pyenv/versions/django/lib/python3.9/site-packages/django/template/engine.py", line 157, in find_template
    template = loader.get_template(name, skip=skip)
  File "/home/user/.pyenv/versions/django/lib/python3.9/site-packages/django/template/loaders/cached.py", line 57, in get_template
    template = super().get_template(template_name, skip)
  File "/home/user/.pyenv/versions/django/lib/python3.9/site-packages/django/template/loaders/base.py", line 28, in get_template
    return Template(
  File "/home/user/.pyenv/versions/django/lib/python3.9/site-packages/django/template/base.py", line 154, in __init__
    self.nodelist = self.compile_nodelist()
  File "/home/user/.pyenv/versions/django/lib/python3.9/site-packages/django/template/base.py", line 200, in compile_nodelist
    return parser.parse()
  File "/home/user/.pyenv/versions/django/lib/python3.9/site-packages/django/template/base.py", line 513, in parse
    raise self.error(token, e)
  File "/home/user/.pyenv/versions/django/lib/python3.9/site-packages/django/template/base.py", line 511, in parse
    compiled_result = compile_func(self, token)
  File "/home/user/.pyenv/versions/django/lib/python3.9/site-packages/django/template/defaulttags.py", line 853, in do_for
    nodelist_loop = parser.parse(
  File "/home/user/.pyenv/versions/django/lib/python3.9/site-packages/django/template/base.py", line 484, in parse
    raise self.error(token, e)
  File "/home/user/.pyenv/versions/django/lib/python3.9/site-packages/django/template/base.py", line 482, in parse
    filter_expression = self.compile_filter(token.contents)
  File "/home/user/.pyenv/versions/django/lib/python3.9/site-packages/django/template/base.py", line 600, in compile_filter
    return FilterExpression(token, self)
  File "/home/user/.pyenv/versions/django/lib/python3.9/site-packages/django/template/base.py", line 703, in __init__
    raise TemplateSyntaxError(
django.template.exceptions.TemplateSyntaxError: Could not parse the remainder: '[0]' from 'line[0]'
"GET /words_list/ HTTP/1.1" 500 153196
Internal Server Error: /words_list/
Traceback (most recent call last):
  File "/home/user/.pyenv/versions/django/lib/python3.9/site-packages/django/core/handlers/exception.py", line 55, in inner
    response = get_response(request)
  File "/home/user/.pyenv/versions/django/lib/python3.9/site-packages/django/core/handlers/base.py", line 197, in _get_response
    response = wrapped_callback(request, *callback_args, **callback_kwargs)
  File "/home/user/stepik_django/maincourse/mainapp/views.py", line 10, in dictionary
    return render(request, 'dictionary.html', content)
  File "/home/user/.pyenv/versions/django/lib/python3.9/site-packages/django/shortcuts.py", line 24, in render
    content = loader.render_to_string(template_name, context, request, using=using)
  File "/home/user/.pyenv/versions/django/lib/python3.9/site-packages/django/template/loader.py", line 61, in render_to_string
    template = get_template(template_name, using=using)
  File "/home/user/.pyenv/versions/django/lib/python3.9/site-packages/django/template/loader.py", line 15, in get_template
    return engine.get_template(template_name)
  File "/home/user/.pyenv/versions/django/lib/python3.9/site-packages/django/template/backends/django.py", line 33, in get_template
    return Template(self.engine.get_template(template_name), self)
  File "/home/user/.pyenv/versions/django/lib/python3.9/site-packages/django/template/engine.py", line 175, in get_template
    template, origin = self.find_template(template_name)
  File "/home/user/.pyenv/versions/django/lib/python3.9/site-packages/django/template/engine.py", line 157, in find_template
    template = loader.get_template(name, skip=skip)
  File "/home/user/.pyenv/versions/django/lib/python3.9/site-packages/django/template/loaders/cached.py", line 57, in get_template
    template = super().get_template(template_name, skip)
  File "/home/user/.pyenv/versions/django/lib/python3.9/site-packages/django/template/loaders/base.py", line 28, in get_template
    return Template(
  File "/home/user/.pyenv/versions/django/lib/python3.9/site-packages/django/template/base.py", line 154, in __init__
    self.nodelist = self.compile_nodelist()
  File "/home/user/.pyenv/versions/django/lib/python3.9/site-packages/django/template/base.py", line 200, in compile_nodelist
    return parser.parse()
  File "/home/user/.pyenv/versions/django/lib/python3.9/site-packages/django/template/base.py", line 513, in parse
    raise self.error(token, e)
  File "/home/user/.pyenv/versions/django/lib/python3.9/site-packages/django/template/base.py", line 511, in parse
    compiled_result = compile_func(self, token)
  File "/home/user/.pyenv/versions/django/lib/python3.9/site-packages/django/template/defaulttags.py", line 853, in do_for
    nodelist_loop = parser.parse(
  File "/home/user/.pyenv/versions/django/lib/python3.9/site-packages/django/template/base.py", line 484, in parse
    raise self.error(token, e)
  File "/home/user/.pyenv/versions/django/lib/python3.9/site-packages/django/template/base.py", line 482, in parse
    filter_expression = self.compile_filter(token.contents)
  File "/home/user/.pyenv/versions/django/lib/python3.9/site-packages/django/template/base.py", line 600, in compile_filter
    return FilterExpression(token, self)
  File "/home/user/.pyenv/versions/django/lib/python3.9/site-packages/django/template/base.py", line 703, in __init__
    raise TemplateSyntaxError(
django.template.exceptions.TemplateSyntaxError: Could not parse the remainder: '[0]' from 'line[0]'
"GET /words_list/ HTTP/1.1" 500 153196
Internal Server Error: /words_list/
Traceback (most recent call last):
  File "/home/user/.pyenv/versions/django/lib/python3.9/site-packages/django/core/handlers/exception.py", line 55, in inner
    response = get_response(request)
  File "/home/user/.pyenv/versions/django/lib/python3.9/site-packages/django/core/handlers/base.py", line 197, in _get_response
    response = wrapped_callback(request, *callback_args, **callback_kwargs)
  File "/home/user/stepik_django/maincourse/mainapp/views.py", line 10, in dictionary
    return render(request, 'dictionary.html', content)
  File "/home/user/.pyenv/versions/django/lib/python3.9/site-packages/django/shortcuts.py", line 24, in render
    content = loader.render_to_string(template_name, context, request, using=using)
  File "/home/user/.pyenv/versions/django/lib/python3.9/site-packages/django/template/loader.py", line 61, in render_to_string
    template = get_template(template_name, using=using)
  File "/home/user/.pyenv/versions/django/lib/python3.9/site-packages/django/template/loader.py", line 15, in get_template
    return engine.get_template(template_name)
  File "/home/user/.pyenv/versions/django/lib/python3.9/site-packages/django/template/backends/django.py", line 33, in get_template
    return Template(self.engine.get_template(template_name), self)
  File "/home/user/.pyenv/versions/django/lib/python3.9/site-packages/django/template/engine.py", line 175, in get_template
    template, origin = self.find_template(template_name)
  File "/home/user/.pyenv/versions/django/lib/python3.9/site-packages/django/template/engine.py", line 157, in find_template
    template = loader.get_template(name, skip=skip)
  File "/home/user/.pyenv/versions/django/lib/python3.9/site-packages/django/template/loaders/cached.py", line 57, in get_template
    template = super().get_template(template_name, skip)
  File "/home/user/.pyenv/versions/django/lib/python3.9/site-packages/django/template/loaders/base.py", line 28, in get_template
    return Template(
  File "/home/user/.pyenv/versions/django/lib/python3.9/site-packages/django/template/base.py", line 154, in __init__
    self.nodelist = self.compile_nodelist()
  File "/home/user/.pyenv/versions/django/lib/python3.9/site-packages/django/template/base.py", line 200, in compile_nodelist
    return parser.parse()
  File "/home/user/.pyenv/versions/django/lib/python3.9/site-packages/django/template/base.py", line 513, in parse
    raise self.error(token, e)
  File "/home/user/.pyenv/versions/django/lib/python3.9/site-packages/django/template/base.py", line 511, in parse
    compiled_result = compile_func(self, token)
  File "/home/user/.pyenv/versions/django/lib/python3.9/site-packages/django/template/defaulttags.py", line 853, in do_for
    nodelist_loop = parser.parse(
  File "/home/user/.pyenv/versions/django/lib/python3.9/site-packages/django/template/base.py", line 484, in parse
    raise self.error(token, e)
  File "/home/user/.pyenv/versions/django/lib/python3.9/site-packages/django/template/base.py", line 482, in parse
    filter_expression = self.compile_filter(token.contents)
  File "/home/user/.pyenv/versions/django/lib/python3.9/site-packages/django/template/base.py", line 600, in compile_filter
    return FilterExpression(token, self)
  File "/home/user/.pyenv/versions/django/lib/python3.9/site-packages/django/template/base.py", line 703, in __init__
    raise TemplateSyntaxError(
django.template.exceptions.TemplateSyntaxError: Could not parse the remainder: '[0]' from 'line[0]'
"GET /words_list/ HTTP/1.1" 500 153256
Internal Server Error: /words_list/
Traceback (most recent call last):
  File "/home/user/.pyenv/versions/django/lib/python3.9/site-packages/django/core/handlers/exception.py", line 55, in inner
    response = get_response(request)
  File "/home/user/.pyenv/versions/django/lib/python3.9/site-packages/django/core/handlers/base.py", line 197, in _get_response
    response = wrapped_callback(request, *callback_args, **callback_kwargs)
  File "/home/user/stepik_django/maincourse/mainapp/views.py", line 10, in dictionary
    return render(request, 'dictionary.html', content)
  File "/home/user/.pyenv/versions/django/lib/python3.9/site-packages/django/shortcuts.py", line 24, in render
    content = loader.render_to_string(template_name, context, request, using=using)
  File "/home/user/.pyenv/versions/django/lib/python3.9/site-packages/django/template/loader.py", line 61, in render_to_string
    template = get_template(template_name, using=using)
  File "/home/user/.pyenv/versions/django/lib/python3.9/site-packages/django/template/loader.py", line 15, in get_template
    return engine.get_template(template_name)
  File "/home/user/.pyenv/versions/django/lib/python3.9/site-packages/django/template/backends/django.py", line 33, in get_template
    return Template(self.engine.get_template(template_name), self)
  File "/home/user/.pyenv/versions/django/lib/python3.9/site-packages/django/template/engine.py", line 175, in get_template
    template, origin = self.find_template(template_name)
  File "/home/user/.pyenv/versions/django/lib/python3.9/site-packages/django/template/engine.py", line 157, in find_template
    template = loader.get_template(name, skip=skip)
  File "/home/user/.pyenv/versions/django/lib/python3.9/site-packages/django/template/loaders/cached.py", line 57, in get_template
    template = super().get_template(template_name, skip)
  File "/home/user/.pyenv/versions/django/lib/python3.9/site-packages/django/template/loaders/base.py", line 28, in get_template
    return Template(
  File "/home/user/.pyenv/versions/django/lib/python3.9/site-packages/django/template/base.py", line 154, in __init__
    self.nodelist = self.compile_nodelist()
  File "/home/user/.pyenv/versions/django/lib/python3.9/site-packages/django/template/base.py", line 200, in compile_nodelist
    return parser.parse()
  File "/home/user/.pyenv/versions/django/lib/python3.9/site-packages/django/template/base.py", line 513, in parse
    raise self.error(token, e)
  File "/home/user/.pyenv/versions/django/lib/python3.9/site-packages/django/template/base.py", line 511, in parse
    compiled_result = compile_func(self, token)
  File "/home/user/.pyenv/versions/django/lib/python3.9/site-packages/django/template/defaulttags.py", line 853, in do_for
    nodelist_loop = parser.parse(
  File "/home/user/.pyenv/versions/django/lib/python3.9/site-packages/django/template/base.py", line 484, in parse
    raise self.error(token, e)
  File "/home/user/.pyenv/versions/django/lib/python3.9/site-packages/django/template/base.py", line 482, in parse
    filter_expression = self.compile_filter(token.contents)
  File "/home/user/.pyenv/versions/django/lib/python3.9/site-packages/django/template/base.py", line 600, in compile_filter
    return FilterExpression(token, self)
  File "/home/user/.pyenv/versions/django/lib/python3.9/site-packages/django/template/base.py", line 703, in __init__
    raise TemplateSyntaxError(
django.template.exceptions.TemplateSyntaxError: Could not parse the remainder: '('-')' from 'elem.split('-')'
"GET /words_list/ HTTP/1.1" 500 153617
Internal Server Error: /words_list/
Traceback (most recent call last):
  File "/home/user/.pyenv/versions/django/lib/python3.9/site-packages/django/core/handlers/exception.py", line 55, in inner
    response = get_response(request)
  File "/home/user/.pyenv/versions/django/lib/python3.9/site-packages/django/core/handlers/base.py", line 197, in _get_response
    response = wrapped_callback(request, *callback_args, **callback_kwargs)
  File "/home/user/stepik_django/maincourse/mainapp/views.py", line 10, in dictionary
    return render(request, 'dictionary.html', content)
  File "/home/user/.pyenv/versions/django/lib/python3.9/site-packages/django/shortcuts.py", line 24, in render
    content = loader.render_to_string(template_name, context, request, using=using)
  File "/home/user/.pyenv/versions/django/lib/python3.9/site-packages/django/template/loader.py", line 61, in render_to_string
    template = get_template(template_name, using=using)
  File "/home/user/.pyenv/versions/django/lib/python3.9/site-packages/django/template/loader.py", line 15, in get_template
    return engine.get_template(template_name)
  File "/home/user/.pyenv/versions/django/lib/python3.9/site-packages/django/template/backends/django.py", line 33, in get_template
    return Template(self.engine.get_template(template_name), self)
  File "/home/user/.pyenv/versions/django/lib/python3.9/site-packages/django/template/engine.py", line 175, in get_template
    template, origin = self.find_template(template_name)
  File "/home/user/.pyenv/versions/django/lib/python3.9/site-packages/django/template/engine.py", line 157, in find_template
    template = loader.get_template(name, skip=skip)
  File "/home/user/.pyenv/versions/django/lib/python3.9/site-packages/django/template/loaders/cached.py", line 57, in get_template
    template = super().get_template(template_name, skip)
  File "/home/user/.pyenv/versions/django/lib/python3.9/site-packages/django/template/loaders/base.py", line 28, in get_template
    return Template(
  File "/home/user/.pyenv/versions/django/lib/python3.9/site-packages/django/template/base.py", line 154, in __init__
    self.nodelist = self.compile_nodelist()
  File "/home/user/.pyenv/versions/django/lib/python3.9/site-packages/django/template/base.py", line 200, in compile_nodelist
    return parser.parse()
  File "/home/user/.pyenv/versions/django/lib/python3.9/site-packages/django/template/base.py", line 513, in parse
    raise self.error(token, e)
  File "/home/user/.pyenv/versions/django/lib/python3.9/site-packages/django/template/base.py", line 511, in parse
    compiled_result = compile_func(self, token)
  File "/home/user/.pyenv/versions/django/lib/python3.9/site-packages/django/template/defaulttags.py", line 853, in do_for
    nodelist_loop = parser.parse(
  File "/home/user/.pyenv/versions/django/lib/python3.9/site-packages/django/template/base.py", line 484, in parse
    raise self.error(token, e)
  File "/home/user/.pyenv/versions/django/lib/python3.9/site-packages/django/template/base.py", line 482, in parse
    filter_expression = self.compile_filter(token.contents)
  File "/home/user/.pyenv/versions/django/lib/python3.9/site-packages/django/template/base.py", line 600, in compile_filter
    return FilterExpression(token, self)
  File "/home/user/.pyenv/versions/django/lib/python3.9/site-packages/django/template/base.py", line 703, in __init__
    raise TemplateSyntaxError(
django.template.exceptions.TemplateSyntaxError: Could not parse the remainder: '[0].split('-')' from 'elem[0].split('-')'
"GET /words_list/ HTTP/1.1" 500 153699
Internal Server Error: /words_list/
Traceback (most recent call last):
  File "/home/user/.pyenv/versions/django/lib/python3.9/site-packages/django/core/handlers/exception.py", line 55, in inner
    response = get_response(request)
  File "/home/user/.pyenv/versions/django/lib/python3.9/site-packages/django/core/handlers/base.py", line 197, in _get_response
    response = wrapped_callback(request, *callback_args, **callback_kwargs)
  File "/home/user/stepik_django/maincourse/mainapp/views.py", line 10, in dictionary
    return render(request, 'dictionary.html', content)
  File "/home/user/.pyenv/versions/django/lib/python3.9/site-packages/django/shortcuts.py", line 24, in render
    content = loader.render_to_string(template_name, context, request, using=using)
  File "/home/user/.pyenv/versions/django/lib/python3.9/site-packages/django/template/loader.py", line 61, in render_to_string
    template = get_template(template_name, using=using)
  File "/home/user/.pyenv/versions/django/lib/python3.9/site-packages/django/template/loader.py", line 15, in get_template
    return engine.get_template(template_name)
  File "/home/user/.pyenv/versions/django/lib/python3.9/site-packages/django/template/backends/django.py", line 33, in get_template
    return Template(self.engine.get_template(template_name), self)
  File "/home/user/.pyenv/versions/django/lib/python3.9/site-packages/django/template/engine.py", line 175, in get_template
    template, origin = self.find_template(template_name)
  File "/home/user/.pyenv/versions/django/lib/python3.9/site-packages/django/template/engine.py", line 157, in find_template
    template = loader.get_template(name, skip=skip)
  File "/home/user/.pyenv/versions/django/lib/python3.9/site-packages/django/template/loaders/cached.py", line 57, in get_template
    template = super().get_template(template_name, skip)
  File "/home/user/.pyenv/versions/django/lib/python3.9/site-packages/django/template/loaders/base.py", line 28, in get_template
    return Template(
  File "/home/user/.pyenv/versions/django/lib/python3.9/site-packages/django/template/base.py", line 154, in __init__
    self.nodelist = self.compile_nodelist()
  File "/home/user/.pyenv/versions/django/lib/python3.9/site-packages/django/template/base.py", line 200, in compile_nodelist
    return parser.parse()
  File "/home/user/.pyenv/versions/django/lib/python3.9/site-packages/django/template/base.py", line 513, in parse
    raise self.error(token, e)
  File "/home/user/.pyenv/versions/django/lib/python3.9/site-packages/django/template/base.py", line 511, in parse
    compiled_result = compile_func(self, token)
  File "/home/user/.pyenv/versions/django/lib/python3.9/site-packages/django/template/defaulttags.py", line 853, in do_for
    nodelist_loop = parser.parse(
  File "/home/user/.pyenv/versions/django/lib/python3.9/site-packages/django/template/base.py", line 484, in parse
    raise self.error(token, e)
  File "/home/user/.pyenv/versions/django/lib/python3.9/site-packages/django/template/base.py", line 482, in parse
    filter_expression = self.compile_filter(token.contents)
  File "/home/user/.pyenv/versions/django/lib/python3.9/site-packages/django/template/base.py", line 600, in compile_filter
    return FilterExpression(token, self)
  File "/home/user/.pyenv/versions/django/lib/python3.9/site-packages/django/template/base.py", line 703, in __init__
    raise TemplateSyntaxError(
django.template.exceptions.TemplateSyntaxError: Could not parse the remainder: '[0].split('-')' from 'elem[0].split('-')'
"GET /words_list/ HTTP/1.1" 500 153699
Internal Server Error: /words_list/
Traceback (most recent call last):
  File "/home/user/.pyenv/versions/django/lib/python3.9/site-packages/django/core/handlers/exception.py", line 55, in inner
    response = get_response(request)
  File "/home/user/.pyenv/versions/django/lib/python3.9/site-packages/django/core/handlers/base.py", line 197, in _get_response
    response = wrapped_callback(request, *callback_args, **callback_kwargs)
  File "/home/user/stepik_django/maincourse/mainapp/views.py", line 10, in dictionary
    return render(request, 'dictionary.html', content)
  File "/home/user/.pyenv/versions/django/lib/python3.9/site-packages/django/shortcuts.py", line 24, in render
    content = loader.render_to_string(template_name, context, request, using=using)
  File "/home/user/.pyenv/versions/django/lib/python3.9/site-packages/django/template/loader.py", line 61, in render_to_string
    template = get_template(template_name, using=using)
  File "/home/user/.pyenv/versions/django/lib/python3.9/site-packages/django/template/loader.py", line 15, in get_template
    return engine.get_template(template_name)
  File "/home/user/.pyenv/versions/django/lib/python3.9/site-packages/django/template/backends/django.py", line 33, in get_template
    return Template(self.engine.get_template(template_name), self)
  File "/home/user/.pyenv/versions/django/lib/python3.9/site-packages/django/template/engine.py", line 175, in get_template
    template, origin = self.find_template(template_name)
  File "/home/user/.pyenv/versions/django/lib/python3.9/site-packages/django/template/engine.py", line 157, in find_template
    template = loader.get_template(name, skip=skip)
  File "/home/user/.pyenv/versions/django/lib/python3.9/site-packages/django/template/loaders/cached.py", line 57, in get_template
    template = super().get_template(template_name, skip)
  File "/home/user/.pyenv/versions/django/lib/python3.9/site-packages/django/template/loaders/base.py", line 28, in get_template
    return Template(
  File "/home/user/.pyenv/versions/django/lib/python3.9/site-packages/django/template/base.py", line 154, in __init__
    self.nodelist = self.compile_nodelist()
  File "/home/user/.pyenv/versions/django/lib/python3.9/site-packages/django/template/base.py", line 200, in compile_nodelist
    return parser.parse()
  File "/home/user/.pyenv/versions/django/lib/python3.9/site-packages/django/template/base.py", line 513, in parse
    raise self.error(token, e)
  File "/home/user/.pyenv/versions/django/lib/python3.9/site-packages/django/template/base.py", line 511, in parse
    compiled_result = compile_func(self, token)
  File "/home/user/.pyenv/versions/django/lib/python3.9/site-packages/django/template/defaulttags.py", line 853, in do_for
    nodelist_loop = parser.parse(
  File "/home/user/.pyenv/versions/django/lib/python3.9/site-packages/django/template/base.py", line 484, in parse
    raise self.error(token, e)
  File "/home/user/.pyenv/versions/django/lib/python3.9/site-packages/django/template/base.py", line 482, in parse
    filter_expression = self.compile_filter(token.contents)
  File "/home/user/.pyenv/versions/django/lib/python3.9/site-packages/django/template/base.py", line 600, in compile_filter
    return FilterExpression(token, self)
  File "/home/user/.pyenv/versions/django/lib/python3.9/site-packages/django/template/base.py", line 703, in __init__
    raise TemplateSyntaxError(
django.template.exceptions.TemplateSyntaxError: Could not parse the remainder: '[0]' from 'elem[0]'
"GET /words_list/ HTTP/1.1" 500 153237
Internal Server Error: /words_list/
Traceback (most recent call last):
  File "/home/user/.pyenv/versions/django/lib/python3.9/site-packages/django/core/handlers/exception.py", line 55, in inner
    response = get_response(request)
  File "/home/user/.pyenv/versions/django/lib/python3.9/site-packages/django/core/handlers/base.py", line 197, in _get_response
    response = wrapped_callback(request, *callback_args, **callback_kwargs)
  File "/home/user/stepik_django/maincourse/mainapp/views.py", line 10, in dictionary
    return render(request, 'dictionary.html', content)
  File "/home/user/.pyenv/versions/django/lib/python3.9/site-packages/django/shortcuts.py", line 24, in render
    content = loader.render_to_string(template_name, context, request, using=using)
  File "/home/user/.pyenv/versions/django/lib/python3.9/site-packages/django/template/loader.py", line 61, in render_to_string
    template = get_template(template_name, using=using)
  File "/home/user/.pyenv/versions/django/lib/python3.9/site-packages/django/template/loader.py", line 15, in get_template
    return engine.get_template(template_name)
  File "/home/user/.pyenv/versions/django/lib/python3.9/site-packages/django/template/backends/django.py", line 33, in get_template
    return Template(self.engine.get_template(template_name), self)
  File "/home/user/.pyenv/versions/django/lib/python3.9/site-packages/django/template/engine.py", line 175, in get_template
    template, origin = self.find_template(template_name)
  File "/home/user/.pyenv/versions/django/lib/python3.9/site-packages/django/template/engine.py", line 157, in find_template
    template = loader.get_template(name, skip=skip)
  File "/home/user/.pyenv/versions/django/lib/python3.9/site-packages/django/template/loaders/cached.py", line 57, in get_template
    template = super().get_template(template_name, skip)
  File "/home/user/.pyenv/versions/django/lib/python3.9/site-packages/django/template/loaders/base.py", line 28, in get_template
    return Template(
  File "/home/user/.pyenv/versions/django/lib/python3.9/site-packages/django/template/base.py", line 154, in __init__
    self.nodelist = self.compile_nodelist()
  File "/home/user/.pyenv/versions/django/lib/python3.9/site-packages/django/template/base.py", line 200, in compile_nodelist
    return parser.parse()
  File "/home/user/.pyenv/versions/django/lib/python3.9/site-packages/django/template/base.py", line 513, in parse
    raise self.error(token, e)
  File "/home/user/.pyenv/versions/django/lib/python3.9/site-packages/django/template/base.py", line 511, in parse
    compiled_result = compile_func(self, token)
  File "/home/user/.pyenv/versions/django/lib/python3.9/site-packages/django/template/defaulttags.py", line 853, in do_for
    nodelist_loop = parser.parse(
  File "/home/user/.pyenv/versions/django/lib/python3.9/site-packages/django/template/base.py", line 484, in parse
    raise self.error(token, e)
  File "/home/user/.pyenv/versions/django/lib/python3.9/site-packages/django/template/base.py", line 482, in parse
    filter_expression = self.compile_filter(token.contents)
  File "/home/user/.pyenv/versions/django/lib/python3.9/site-packages/django/template/base.py", line 600, in compile_filter
    return FilterExpression(token, self)
  File "/home/user/.pyenv/versions/django/lib/python3.9/site-packages/django/template/base.py", line 703, in __init__
    raise TemplateSyntaxError(
django.template.exceptions.TemplateSyntaxError: Could not parse the remainder: '\n' from 'elem\n'
"GET /words_list/ HTTP/1.1" 500 153222
Internal Server Error: /words_list/
Traceback (most recent call last):
  File "/home/user/.pyenv/versions/django/lib/python3.9/site-packages/django/core/handlers/exception.py", line 55, in inner
    response = get_response(request)
  File "/home/user/.pyenv/versions/django/lib/python3.9/site-packages/django/core/handlers/base.py", line 197, in _get_response
    response = wrapped_callback(request, *callback_args, **callback_kwargs)
  File "/home/user/stepik_django/maincourse/mainapp/views.py", line 10, in dictionary
    return render(request, 'dictionary.html', content)
  File "/home/user/.pyenv/versions/django/lib/python3.9/site-packages/django/shortcuts.py", line 24, in render
    content = loader.render_to_string(template_name, context, request, using=using)
  File "/home/user/.pyenv/versions/django/lib/python3.9/site-packages/django/template/loader.py", line 61, in render_to_string
    template = get_template(template_name, using=using)
  File "/home/user/.pyenv/versions/django/lib/python3.9/site-packages/django/template/loader.py", line 15, in get_template
    return engine.get_template(template_name)
  File "/home/user/.pyenv/versions/django/lib/python3.9/site-packages/django/template/backends/django.py", line 33, in get_template
    return Template(self.engine.get_template(template_name), self)
  File "/home/user/.pyenv/versions/django/lib/python3.9/site-packages/django/template/engine.py", line 175, in get_template
    template, origin = self.find_template(template_name)
  File "/home/user/.pyenv/versions/django/lib/python3.9/site-packages/django/template/engine.py", line 157, in find_template
    template = loader.get_template(name, skip=skip)
  File "/home/user/.pyenv/versions/django/lib/python3.9/site-packages/django/template/loaders/cached.py", line 57, in get_template
    template = super().get_template(template_name, skip)
  File "/home/user/.pyenv/versions/django/lib/python3.9/site-packages/django/template/loaders/base.py", line 28, in get_template
    return Template(
  File "/home/user/.pyenv/versions/django/lib/python3.9/site-packages/django/template/base.py", line 154, in __init__
    self.nodelist = self.compile_nodelist()
  File "/home/user/.pyenv/versions/django/lib/python3.9/site-packages/django/template/base.py", line 200, in compile_nodelist
    return parser.parse()
  File "/home/user/.pyenv/versions/django/lib/python3.9/site-packages/django/template/base.py", line 513, in parse
    raise self.error(token, e)
  File "/home/user/.pyenv/versions/django/lib/python3.9/site-packages/django/template/base.py", line 511, in parse
    compiled_result = compile_func(self, token)
  File "/home/user/.pyenv/versions/django/lib/python3.9/site-packages/django/template/defaulttags.py", line 853, in do_for
    nodelist_loop = parser.parse(
  File "/home/user/.pyenv/versions/django/lib/python3.9/site-packages/django/template/base.py", line 513, in parse
    raise self.error(token, e)
  File "/home/user/.pyenv/versions/django/lib/python3.9/site-packages/django/template/base.py", line 511, in parse
    compiled_result = compile_func(self, token)
  File "/home/user/.pyenv/versions/django/lib/python3.9/site-packages/django/template/defaulttags.py", line 839, in do_for
    raise TemplateSyntaxError(
django.template.exceptions.TemplateSyntaxError: 'for' statements should use the format 'for x in y': for var = elem.split('-')
"GET /words_list/ HTTP/1.1" 500 151785
Internal Server Error: /words_list/
Traceback (most recent call last):
  File "/home/user/.pyenv/versions/django/lib/python3.9/site-packages/django/core/handlers/exception.py", line 55, in inner
    response = get_response(request)
  File "/home/user/.pyenv/versions/django/lib/python3.9/site-packages/django/core/handlers/base.py", line 197, in _get_response
    response = wrapped_callback(request, *callback_args, **callback_kwargs)
  File "/home/user/stepik_django/maincourse/mainapp/views.py", line 17, in dictionary
    return render(request, 'dictionary.html', content)
  File "/home/user/.pyenv/versions/django/lib/python3.9/site-packages/django/shortcuts.py", line 24, in render
    content = loader.render_to_string(template_name, context, request, using=using)
  File "/home/user/.pyenv/versions/django/lib/python3.9/site-packages/django/template/loader.py", line 61, in render_to_string
    template = get_template(template_name, using=using)
  File "/home/user/.pyenv/versions/django/lib/python3.9/site-packages/django/template/loader.py", line 15, in get_template
    return engine.get_template(template_name)
  File "/home/user/.pyenv/versions/django/lib/python3.9/site-packages/django/template/backends/django.py", line 33, in get_template
    return Template(self.engine.get_template(template_name), self)
  File "/home/user/.pyenv/versions/django/lib/python3.9/site-packages/django/template/engine.py", line 175, in get_template
    template, origin = self.find_template(template_name)
  File "/home/user/.pyenv/versions/django/lib/python3.9/site-packages/django/template/engine.py", line 157, in find_template
    template = loader.get_template(name, skip=skip)
  File "/home/user/.pyenv/versions/django/lib/python3.9/site-packages/django/template/loaders/cached.py", line 57, in get_template
    template = super().get_template(template_name, skip)
  File "/home/user/.pyenv/versions/django/lib/python3.9/site-packages/django/template/loaders/base.py", line 28, in get_template
    return Template(
  File "/home/user/.pyenv/versions/django/lib/python3.9/site-packages/django/template/base.py", line 154, in __init__
    self.nodelist = self.compile_nodelist()
  File "/home/user/.pyenv/versions/django/lib/python3.9/site-packages/django/template/base.py", line 200, in compile_nodelist
    return parser.parse()
  File "/home/user/.pyenv/versions/django/lib/python3.9/site-packages/django/template/base.py", line 513, in parse
    raise self.error(token, e)
  File "/home/user/.pyenv/versions/django/lib/python3.9/site-packages/django/template/base.py", line 511, in parse
    compiled_result = compile_func(self, token)
  File "/home/user/.pyenv/versions/django/lib/python3.9/site-packages/django/template/defaulttags.py", line 839, in do_for
    raise TemplateSyntaxError(
django.template.exceptions.TemplateSyntaxError: 'for' statements should use the format 'for x in y': for word, translate in context.words, context.translates
"GET /words_list/ HTTP/1.1" 500 136871
Internal Server Error: /words_list/
Traceback (most recent call last):
  File "/home/user/.pyenv/versions/django/lib/python3.9/site-packages/django/core/handlers/exception.py", line 55, in inner
    response = get_response(request)
  File "/home/user/.pyenv/versions/django/lib/python3.9/site-packages/django/core/handlers/base.py", line 197, in _get_response
    response = wrapped_callback(request, *callback_args, **callback_kwargs)
  File "/home/user/stepik_django/maincourse/mainapp/views.py", line 16, in dictionary
    for a, b in words, translates:
ValueError: too many values to unpack (expected 2)
"GET /words_list/ HTTP/1.1" 500 67561
Internal Server Error: /words_list/
Traceback (most recent call last):
  File "/home/user/.pyenv/versions/django/lib/python3.9/site-packages/django/core/handlers/exception.py", line 55, in inner
    response = get_response(request)
  File "/home/user/.pyenv/versions/django/lib/python3.9/site-packages/django/core/handlers/base.py", line 197, in _get_response
    response = wrapped_callback(request, *callback_args, **callback_kwargs)
  File "/home/user/stepik_django/maincourse/mainapp/views.py", line 18, in dictionary
    return render(request, 'dictionary.html', content)
  File "/home/user/.pyenv/versions/django/lib/python3.9/site-packages/django/shortcuts.py", line 24, in render
    content = loader.render_to_string(template_name, context, request, using=using)
  File "/home/user/.pyenv/versions/django/lib/python3.9/site-packages/django/template/loader.py", line 62, in render_to_string
    return template.render(context, request)
  File "/home/user/.pyenv/versions/django/lib/python3.9/site-packages/django/template/backends/django.py", line 57, in render
    context = make_context(
  File "/home/user/.pyenv/versions/django/lib/python3.9/site-packages/django/template/context.py", line 278, in make_context
    raise TypeError(
TypeError: context must be a dict rather than list.
"GET /words_list/ HTTP/1.1" 500 84399
Internal Server Error: /words_list/
Traceback (most recent call last):
  File "/home/user/.pyenv/versions/django/lib/python3.9/site-packages/django/core/handlers/exception.py", line 55, in inner
    response = get_response(request)
  File "/home/user/.pyenv/versions/django/lib/python3.9/site-packages/django/core/handlers/base.py", line 197, in _get_response
    response = wrapped_callback(request, *callback_args, **callback_kwargs)
  File "/home/user/stepik_django/maincourse/mainapp/views.py", line 20, in dictionary
    return render(request, 'dictionary.html', content)
  File "/home/user/.pyenv/versions/django/lib/python3.9/site-packages/django/shortcuts.py", line 24, in render
    content = loader.render_to_string(template_name, context, request, using=using)
  File "/home/user/.pyenv/versions/django/lib/python3.9/site-packages/django/template/loader.py", line 62, in render_to_string
    return template.render(context, request)
  File "/home/user/.pyenv/versions/django/lib/python3.9/site-packages/django/template/backends/django.py", line 57, in render
    context = make_context(
  File "/home/user/.pyenv/versions/django/lib/python3.9/site-packages/django/template/context.py", line 278, in make_context
    raise TypeError(
TypeError: context must be a dict rather than list.
"GET /words_list/ HTTP/1.1" 500 84484
Internal Server Error: /words_list/
Traceback (most recent call last):
  File "/home/user/.pyenv/versions/django/lib/python3.9/site-packages/django/core/handlers/exception.py", line 55, in inner
    response = get_response(request)
  File "/home/user/.pyenv/versions/django/lib/python3.9/site-packages/django/core/handlers/base.py", line 197, in _get_response
    response = wrapped_callback(request, *callback_args, **callback_kwargs)
  File "/home/user/stepik_django/maincourse/mainapp/views.py", line 15, in dictionary
    return render(request, 'dictionary.html', context)
  File "/home/user/.pyenv/versions/django/lib/python3.9/site-packages/django/shortcuts.py", line 24, in render
    content = loader.render_to_string(template_name, context, request, using=using)
  File "/home/user/.pyenv/versions/django/lib/python3.9/site-packages/django/template/loader.py", line 61, in render_to_string
    template = get_template(template_name, using=using)
  File "/home/user/.pyenv/versions/django/lib/python3.9/site-packages/django/template/loader.py", line 15, in get_template
    return engine.get_template(template_name)
  File "/home/user/.pyenv/versions/django/lib/python3.9/site-packages/django/template/backends/django.py", line 33, in get_template
    return Template(self.engine.get_template(template_name), self)
  File "/home/user/.pyenv/versions/django/lib/python3.9/site-packages/django/template/engine.py", line 175, in get_template
    template, origin = self.find_template(template_name)
  File "/home/user/.pyenv/versions/django/lib/python3.9/site-packages/django/template/engine.py", line 157, in find_template
    template = loader.get_template(name, skip=skip)
  File "/home/user/.pyenv/versions/django/lib/python3.9/site-packages/django/template/loaders/cached.py", line 57, in get_template
    template = super().get_template(template_name, skip)
  File "/home/user/.pyenv/versions/django/lib/python3.9/site-packages/django/template/loaders/base.py", line 28, in get_template
    return Template(
  File "/home/user/.pyenv/versions/django/lib/python3.9/site-packages/django/template/base.py", line 154, in __init__
    self.nodelist = self.compile_nodelist()
  File "/home/user/.pyenv/versions/django/lib/python3.9/site-packages/django/template/base.py", line 200, in compile_nodelist
    return parser.parse()
  File "/home/user/.pyenv/versions/django/lib/python3.9/site-packages/django/template/base.py", line 513, in parse
    raise self.error(token, e)
  File "/home/user/.pyenv/versions/django/lib/python3.9/site-packages/django/template/base.py", line 511, in parse
    compiled_result = compile_func(self, token)
  File "/home/user/.pyenv/versions/django/lib/python3.9/site-packages/django/template/defaulttags.py", line 848, in do_for
    raise TemplateSyntaxError(
django.template.exceptions.TemplateSyntaxError: 'for' tag received an invalid argument: for for w, t in context.items
"GET /words_list/ HTTP/1.1" 500 137300
Internal Server Error: /words_list/
Traceback (most recent call last):
  File "/home/user/.pyenv/versions/django/lib/python3.9/site-packages/django/template/base.py", line 505, in parse
    compile_func = self.tags[command]
KeyError: 'endfor'

During handling of the above exception, another exception occurred:

Traceback (most recent call last):
  File "/home/user/.pyenv/versions/django/lib/python3.9/site-packages/django/core/handlers/exception.py", line 55, in inner
    response = get_response(request)
  File "/home/user/.pyenv/versions/django/lib/python3.9/site-packages/django/core/handlers/base.py", line 197, in _get_response
    response = wrapped_callback(request, *callback_args, **callback_kwargs)
  File "/home/user/stepik_django/maincourse/mainapp/views.py", line 15, in dictionary
    return render(request, 'dictionary.html', context)
  File "/home/user/.pyenv/versions/django/lib/python3.9/site-packages/django/shortcuts.py", line 24, in render
    content = loader.render_to_string(template_name, context, request, using=using)
  File "/home/user/.pyenv/versions/django/lib/python3.9/site-packages/django/template/loader.py", line 61, in render_to_string
    template = get_template(template_name, using=using)
  File "/home/user/.pyenv/versions/django/lib/python3.9/site-packages/django/template/loader.py", line 15, in get_template
    return engine.get_template(template_name)
  File "/home/user/.pyenv/versions/django/lib/python3.9/site-packages/django/template/backends/django.py", line 33, in get_template
    return Template(self.engine.get_template(template_name), self)
  File "/home/user/.pyenv/versions/django/lib/python3.9/site-packages/django/template/engine.py", line 175, in get_template
    template, origin = self.find_template(template_name)
  File "/home/user/.pyenv/versions/django/lib/python3.9/site-packages/django/template/engine.py", line 157, in find_template
    template = loader.get_template(name, skip=skip)
  File "/home/user/.pyenv/versions/django/lib/python3.9/site-packages/django/template/loaders/cached.py", line 57, in get_template
    template = super().get_template(template_name, skip)
  File "/home/user/.pyenv/versions/django/lib/python3.9/site-packages/django/template/loaders/base.py", line 28, in get_template
    return Template(
  File "/home/user/.pyenv/versions/django/lib/python3.9/site-packages/django/template/base.py", line 154, in __init__
    self.nodelist = self.compile_nodelist()
  File "/home/user/.pyenv/versions/django/lib/python3.9/site-packages/django/template/base.py", line 200, in compile_nodelist
    return parser.parse()
  File "/home/user/.pyenv/versions/django/lib/python3.9/site-packages/django/template/base.py", line 507, in parse
    self.invalid_block_tag(token, command, parse_until)
  File "/home/user/.pyenv/versions/django/lib/python3.9/site-packages/django/template/base.py", line 568, in invalid_block_tag
    raise self.error(
django.template.exceptions.TemplateSyntaxError: Invalid block tag on line 16: 'endfor'. Did you forget to register or load this tag?
"GET /words_list/ HTTP/1.1" 500 135204
Invalid HTTP_HOST header: '4eec-5-141-101-144.ngrok-free.app'. You may need to add '4eec-5-141-101-144.ngrok-free.app' to ALLOWED_HOSTS.
Traceback (most recent call last):
  File "/home/user/.pyenv/versions/django/lib/python3.9/site-packages/django/core/handlers/exception.py", line 55, in inner
    response = get_response(request)
  File "/home/user/.pyenv/versions/django/lib/python3.9/site-packages/django/utils/deprecation.py", line 133, in __call__
    response = self.process_request(request)
  File "/home/user/.pyenv/versions/django/lib/python3.9/site-packages/django/middleware/common.py", line 48, in process_request
    host = request.get_host()
  File "/home/user/.pyenv/versions/django/lib/python3.9/site-packages/django/http/request.py", line 150, in get_host
    raise DisallowedHost(msg)
django.core.exceptions.DisallowedHost: Invalid HTTP_HOST header: '4eec-5-141-101-144.ngrok-free.app'. You may need to add '4eec-5-141-101-144.ngrok-free.app' to ALLOWED_HOSTS.
Invalid HTTP_HOST header: '4eec-5-141-101-144.ngrok-free.app'. You may need to add '4eec-5-141-101-144.ngrok-free.app' to ALLOWED_HOSTS.
Traceback (most recent call last):
  File "/home/user/.pyenv/versions/django/lib/python3.9/site-packages/django/core/handlers/exception.py", line 55, in inner
    response = get_response(request)
  File "/home/user/.pyenv/versions/django/lib/python3.9/site-packages/django/utils/deprecation.py", line 133, in __call__
    response = self.process_request(request)
  File "/home/user/.pyenv/versions/django/lib/python3.9/site-packages/django/middleware/common.py", line 48, in process_request
    host = request.get_host()
  File "/home/user/.pyenv/versions/django/lib/python3.9/site-packages/django/http/request.py", line 150, in get_host
    raise DisallowedHost(msg)
django.core.exceptions.DisallowedHost: Invalid HTTP_HOST header: '4eec-5-141-101-144.ngrok-free.app'. You may need to add '4eec-5-141-101-144.ngrok-free.app' to ALLOWED_HOSTS.
Invalid HTTP_HOST header: 'e27c-5-141-101-144.ngrok-free.app'. You may need to add 'e27c-5-141-101-144.ngrok-free.app' to ALLOWED_HOSTS.
Traceback (most recent call last):
  File "/home/user/.pyenv/versions/django/lib/python3.9/site-packages/django/core/handlers/exception.py", line 55, in inner
    response = get_response(request)
  File "/home/user/.pyenv/versions/django/lib/python3.9/site-packages/django/utils/deprecation.py", line 133, in __call__
    response = self.process_request(request)
  File "/home/user/.pyenv/versions/django/lib/python3.9/site-packages/django/middleware/common.py", line 48, in process_request
    host = request.get_host()
  File "/home/user/.pyenv/versions/django/lib/python3.9/site-packages/django/http/request.py", line 150, in get_host
    raise DisallowedHost(msg)
django.core.exceptions.DisallowedHost: Invalid HTTP_HOST header: 'e27c-5-141-101-144.ngrok-free.app'. You may need to add 'e27c-5-141-101-144.ngrok-free.app' to ALLOWED_HOSTS.
Invalid HTTP_HOST header: 'e27c-5-141-101-144.ngrok-free.app'. You may need to add 'e27c-5-141-101-144.ngrok-free.app' to ALLOWED_HOSTS.
Traceback (most recent call last):
  File "/home/user/.pyenv/versions/django/lib/python3.9/site-packages/django/core/handlers/exception.py", line 55, in inner
    response = get_response(request)
  File "/home/user/.pyenv/versions/django/lib/python3.9/site-packages/django/utils/deprecation.py", line 133, in __call__
    response = self.process_request(request)
  File "/home/user/.pyenv/versions/django/lib/python3.9/site-packages/django/middleware/common.py", line 48, in process_request
    host = request.get_host()
  File "/home/user/.pyenv/versions/django/lib/python3.9/site-packages/django/http/request.py", line 150, in get_host
    raise DisallowedHost(msg)
django.core.exceptions.DisallowedHost: Invalid HTTP_HOST header: 'e27c-5-141-101-144.ngrok-free.app'. You may need to add 'e27c-5-141-101-144.ngrok-free.app' to ALLOWED_HOSTS.
Invalid HTTP_HOST header: '57f1-5-141-101-144.ngrok-free.app'. You may need to add '57f1-5-141-101-144.ngrok-free.app' to ALLOWED_HOSTS.
Traceback (most recent call last):
  File "/home/user/.pyenv/versions/django/lib/python3.9/site-packages/django/core/handlers/exception.py", line 55, in inner
    response = get_response(request)
  File "/home/user/.pyenv/versions/django/lib/python3.9/site-packages/django/utils/deprecation.py", line 133, in __call__
    response = self.process_request(request)
  File "/home/user/.pyenv/versions/django/lib/python3.9/site-packages/django/middleware/common.py", line 48, in process_request
    host = request.get_host()
  File "/home/user/.pyenv/versions/django/lib/python3.9/site-packages/django/http/request.py", line 150, in get_host
    raise DisallowedHost(msg)
django.core.exceptions.DisallowedHost: Invalid HTTP_HOST header: '57f1-5-141-101-144.ngrok-free.app'. You may need to add '57f1-5-141-101-144.ngrok-free.app' to ALLOWED_HOSTS.
Invalid HTTP_HOST header: '57f1-5-141-101-144.ngrok-free.app'. You may need to add '57f1-5-141-101-144.ngrok-free.app' to ALLOWED_HOSTS.
Traceback (most recent call last):
  File "/home/user/.pyenv/versions/django/lib/python3.9/site-packages/django/core/handlers/exception.py", line 55, in inner
    response = get_response(request)
  File "/home/user/.pyenv/versions/django/lib/python3.9/site-packages/django/utils/deprecation.py", line 133, in __call__
    response = self.process_request(request)
  File "/home/user/.pyenv/versions/django/lib/python3.9/site-packages/django/middleware/common.py", line 48, in process_request
    host = request.get_host()
  File "/home/user/.pyenv/versions/django/lib/python3.9/site-packages/django/http/request.py", line 150, in get_host
    raise DisallowedHost(msg)
django.core.exceptions.DisallowedHost: Invalid HTTP_HOST header: '57f1-5-141-101-144.ngrok-free.app'. You may need to add '57f1-5-141-101-144.ngrok-free.app' to ALLOWED_HOSTS.
Internal Server Error: /add_word/
Traceback (most recent call last):
  File "/home/user/.pyenv/versions/django/lib/python3.9/site-packages/django/utils/datastructures.py", line 84, in __getitem__
    list_ = super().__getitem__(key)
KeyError: 'word'

During handling of the above exception, another exception occurred:

Traceback (most recent call last):
  File "/home/user/.pyenv/versions/django/lib/python3.9/site-packages/django/core/handlers/exception.py", line 55, in inner
    response = get_response(request)
  File "/home/user/.pyenv/versions/django/lib/python3.9/site-packages/django/core/handlers/base.py", line 197, in _get_response
    response = wrapped_callback(request, *callback_args, **callback_kwargs)
  File "/home/user/stepik_django/maincourse/mainapp/views.py", line 26, in add_word
    word = data['word']
  File "/home/user/.pyenv/versions/django/lib/python3.9/site-packages/django/utils/datastructures.py", line 86, in __getitem__
    raise MultiValueDictKeyError(key)
django.utils.datastructures.MultiValueDictKeyError: 'word'
"POST /add_word/ HTTP/1.1" 500 74678
Internal Server Error: /add_word/
Traceback (most recent call last):
  File "/home/user/.pyenv/versions/django/lib/python3.9/site-packages/django/utils/datastructures.py", line 84, in __getitem__
    list_ = super().__getitem__(key)
KeyError: 'word'

During handling of the above exception, another exception occurred:

Traceback (most recent call last):
  File "/home/user/.pyenv/versions/django/lib/python3.9/site-packages/django/core/handlers/exception.py", line 55, in inner
    response = get_response(request)
  File "/home/user/.pyenv/versions/django/lib/python3.9/site-packages/django/core/handlers/base.py", line 197, in _get_response
    response = wrapped_callback(request, *callback_args, **callback_kwargs)
  File "/home/user/stepik_django/maincourse/mainapp/views.py", line 26, in add_word
    word = data['word']
  File "/home/user/.pyenv/versions/django/lib/python3.9/site-packages/django/utils/datastructures.py", line 86, in __getitem__
    raise MultiValueDictKeyError(key)
django.utils.datastructures.MultiValueDictKeyError: 'word'
"POST /add_word/ HTTP/1.1" 500 74678
